<?xml version="1.0" encoding="utf-8"?>
<!-- This URDF was automatically created by SolidWorks to URDF Exporter! Originally created by Stephen Brawner (brawner@gmail.com) 
     Commit Version: 1.6.0-1-g15f4949  Build Version: 1.6.7594.29634
     For more information, please see http://wiki.ros.org/sw_urdf_exporter -->
<robot
  name="RM65-B">
  <link
    name="base_link">
    <inertial>
      <origin
        xyz="-0.00049987 -5.2709E-05 0.060019"
        rpy="0 0 0" />
      <mass
        value="1.862" />
      <inertia
        ixx="0.0017232"
        ixy="-3.1058E-06"
        ixz="3.7924E-05"
        iyy="0.0017051"
        iyz="-1.3691E-06"
        izz="0.00090158" />
    </inertial>
    <visual>
      <origin
        xyz="0 0 0"
        rpy="0 0 0" />
      <geometry>
        <mesh
          filename="package://RM65-B/meshes/base_link.STL" />
      </geometry>
      <material
        name="arm_base">
        <color
          rgba="0.3 0.42 0.58 1" />
      </material>
    </visual>
    <collision>
      <origin
        xyz="0 0 0"
        rpy="0 0 0" />
      <geometry>
        <mesh
          filename="package://RM65-B/meshes/base_link.STL" />
      </geometry>
    </collision>
  </link>
  <link
    name="link_1">
    <inertial>
      <origin
        xyz="0.000941 0.007803 -0.10744"
        rpy="0 0 0" />
      <mass
        value="1.51" />
      <inertia
        ixx="0.002662223"
        ixy="-0.000026849"
        ixz="-0.000013775"
        iyy="0.002331685"
        iyz="-0.000078667"
        izz="0.001663712" />
    </inertial>
    <visual>
      <origin
        xyz="0 0 0"
        rpy="0 0 0" />
      <geometry>
        <mesh
          filename="package://RM65-B/meshes/link_1.STL" />
      </geometry>
      <material
        name="arm_link_1">
        <color
          rgba="0.42 0.56 0.72 1" />
      </material>
    </visual>
    <collision>
      <origin
        xyz="0 0 0"
        rpy="0 0 0" />
      <geometry>
        <mesh
          filename="package://RM65-B/meshes/link_1.STL" />
      </geometry>
    </collision>
  </link>
  <joint
    name="joint_1"
    type="revolute">
    <origin
      xyz="0 0 0.2405"
      rpy="0 0 0" />
    <parent
      link="base_link" />
    <child
      link="link_1" />
    <axis
      xyz="0 0 1" />
    <limit
      lower="-3.106"
      upper="3.106"
      effort="60"
      velocity="3.14" />
  </joint>
  <link
    name="link_2">
    <inertial>
      <origin
        xyz="0.183722 0.000103 -0.001665"
        rpy="0 0 0" />
      <mass
        value="1.653" />
      <inertia
        ixx="0.001706953"
        ixy="-0.000006995"
        ixz="0.001809254"
        iyy="0.014713776"
        iyz="0.000006223"
        izz="0.014239805" />
    </inertial>
    <visual>
      <origin
        xyz="0 0 0"
        rpy="0 0 0" />
      <geometry>
        <mesh
          filename="package://RM65-B/meshes/link_2.STL" />
      </geometry>
      <material
        name="arm_link_2">
        <color
          rgba="0.38 0.5 0.68 1" />
      </material>
    </visual>
    <collision>
      <origin
        xyz="0 0 0"
        rpy="0 0 0" />
      <geometry>
        <mesh
          filename="package://RM65-B/meshes/link_2.STL" />
      </geometry>
    </collision>
  </link>
  <joint
    name="joint_2"
    type="revolute">
    <origin
      xyz="0 0 0"
      rpy="1.5708 -1.5708 0" />
    <parent
      link="link_1" />
    <child
      link="link_2" />
    <axis
      xyz="0 0 1" />
    <limit
      lower="-2.2689"
      upper="2.2689"
      effort="60"
      velocity="3.14" />
  </joint>
  <link
    name="link_3">
    <inertial>
      <origin
        xyz="0.000029 -0.090105 0.004039"
        rpy="0 0 0" />
      <mass
        value="0.726" />
      <inertia
        ixx="0.001350874"
        ixy="0.000001069"
        ixz="-0.000000228"
        iyy="0.000360021"
        iyz="-0.000219904"
        izz="0.001331598" />
    </inertial>
    <visual>
      <origin
        xyz="0 0 0"
        rpy="0 0 0" />
      <geometry>
        <mesh
          filename="package://RM65-B/meshes/link_3.STL" />
      </geometry>
      <material
        name="arm_link_3">
        <color
          rgba="0.45 0.6 0.78 1" />
      </material>
    </visual>
    <collision>
      <origin
        xyz="0 0 0"
        rpy="0 0 0" />
      <geometry>
        <mesh
          filename="package://RM65-B/meshes/link_3.STL" />
      </geometry>
    </collision>
  </link>
  <joint
    name="joint_3"
    type="revolute">
    <origin
      xyz="0.256 0 0"
      rpy="0 0 1.5708" />
    <parent
      link="link_2" />
    <child
      link="link_3" />
    <axis
      xyz="0 0 1" />
    <limit
      lower="-2.356"
      upper="2.356"
      effort="30"
      velocity="3.14" />
  </joint>
  <link
    name="link_4">
    <inertial>
      <origin
        xyz="0.000007 -0.009486 -0.008041"
        rpy="0 0 0" />
      <mass
        value="0.671" />
      <inertia
        ixx="0.000690221"
        ixy="-0.000000865"
        ixz="-0.000000692"
        iyy="0.000552834"
        iyz="0.000016411"
        izz="0.000425835" />
    </inertial>
    <visual>
      <origin
        xyz="0 0 0"
        rpy="0 0 0" />
      <geometry>
        <mesh
          filename="package://RM65-B/meshes/link_4.STL" />
      </geometry>
      <material
        name="arm_link_4">
        <color
          rgba="0.36 0.48 0.64 1" />
      </material>
    </visual>
    <collision>
      <origin
        xyz="0 0 0"
        rpy="0 0 0" />
      <geometry>
        <mesh
          filename="package://RM65-B/meshes/link_4.STL" />
      </geometry>
    </collision>
  </link>
  <joint
    name="joint_4"
    type="revolute">
    <origin
      xyz="0 -0.21 0"
      rpy="1.5708 0 0" />
    <parent
      link="link_3" />
    <child
      link="link_4" />
    <axis
      xyz="0 0 1" />
    <limit
      lower="-3.106"
      upper="3.106"
      effort="10"
      velocity="3.14" />
  </joint>
  <link
    name="link_5">
    <inertial>
      <origin
        xyz="0.000032 -0.083769 0.002326"
        rpy="0 0 0" />
      <mass
        value="0.647" />
      <inertia
        ixx="0.000834052"
        ixy="0.000000952"
        ixz="-0.000000257"
        iyy="0.000281767"
        iyz="-0.000111750"
        izz="0.000821714" />
    </inertial>
    <visual>
      <origin
        xyz="0 0 0"
        rpy="0 0 0" />
      <geometry>
        <mesh
          filename="package://RM65-B/meshes/link_5.STL" />
      </geometry>
      <material
        name="arm_link_5">
        <color
          rgba="0.4 0.54 0.7 1" />
      </material>
    </visual>
    <collision>
      <origin
        xyz="0 0 0"
        rpy="0 0 0" />
      <geometry>
        <mesh
          filename="package://RM65-B/meshes/link_5.STL" />
      </geometry>
    </collision>
  </link>
  <joint
    name="joint_5"
    type="revolute">
    <origin
      xyz="0 0 0"
      rpy="-1.5708 0 0" />
    <parent
      link="link_4" />
    <child
      link="link_5" />
    <axis
      xyz="0 0 1" />
    <limit
      lower="-2.234"
      upper="2.234"
      effort="10"
      velocity="3.14" />
  </joint>
  <link
    name="link_6">
    <inertial>
      <origin
        xyz="-0.000569 0.00029 -0.010569"
        rpy="0 0 0" />
      <mass
        value="0.104" />
      <inertia
        ixx="3.043E-05"
        ixy="2.622E-09"
        ixz="2.199E-08"
        iyy="3.604E-05"
        iyz="1.195E-08"
        izz="5.52E-05" />
    </inertial>
    <visual>
      <origin
        xyz="0 0 0"
        rpy="0 0 0" />
      <geometry>
        <mesh
          filename="package://RM65-B/meshes/link_6.STL" />
      </geometry>
      <material
        name="arm_link_6">
        <color
          rgba="0.32 0.44 0.6 1" />
      </material>
    </visual>
    <visual>
      <origin
        xyz="0 0 -0.055"
        rpy="0 0 0" />
      <geometry>
        <cylinder
          radius="0.016"
          length="0.11" />
      </geometry>
      <material
        name="arm_link_6_bridge">
        <color
          rgba="0.32 0.44 0.6 1" />
      </material>
    </visual>
    <collision>
      <origin
        xyz="0 0 0"
        rpy="0 0 0" />
      <geometry>
        <mesh
          filename="package://RM65-B/meshes/link_6.STL" />
      </geometry>
    </collision>
    <collision>
      <origin
        xyz="0 0 -0.055"
        rpy="0 0 0" />
      <geometry>
        <cylinder
          radius="0.016"
          length="0.11" />
      </geometry>
    </collision>
  </link>
  <joint
    name="joint_6"
    type="revolute">
    <origin
      xyz="0 -0.144 0"
      rpy="1.5708 0 0" />
    <parent
      link="link_5" />
    <child
      link="link_6" />
    <axis
      xyz="0 0 1" />
    <limit
      lower="-6.28"
      upper="6.28"
      effort="10"
      velocity="3.14" />
  </joint>
  <link
    name="endoscope_tool">
    <inertial>
      <origin
        xyz="0 0 0.18"
        rpy="0 0 0" />
      <mass
        value="0.22" />
      <inertia
        ixx="0.0015"
        ixy="0"
        ixz="0"
        iyy="0.0015"
        iyz="0"
        izz="0.0002" />
    </inertial>
    <visual>
      <origin
        xyz="0 0 0.012"
        rpy="0 0 0" />
      <geometry>
        <cylinder
          radius="0.018"
          length="0.024" />
      </geometry>
      <material
        name="tool_adapter">
        <color
          rgba="0.68 0.7 0.74 1" />
      </material>
    </visual>
    <visual>
      <origin
        xyz="-0.017076289 -0.019918535 0.024"
        rpy="0 0 0" />
      <geometry>
        <mesh
          filename="en.STL"
          scale="0.001 0.001 0.001" />
      </geometry>
      <material
        name="endoscope_body">
        <color
          rgba="0.78 0.8 0.84 1" />
      </material>
    </visual>
    <visual>
      <origin
        xyz="-0.018953737 -0.018953737 0.024"
        rpy="0 0 0" />
      <geometry>
        <mesh
          filename="camera.STL"
          scale="0.001 0.001 0.001" />
      </geometry>
      <material
        name="camera_body">
        <color
          rgba="0.92 0.94 0.98 1" />
      </material>
    </visual>
    <collision>
      <origin
        xyz="0 0 0.012"
        rpy="0 0 0" />
      <geometry>
        <cylinder
          radius="0.018"
          length="0.024" />
      </geometry>
    </collision>
    <collision>
      <origin
        xyz="-0.017076289 -0.019918535 0.024"
        rpy="0 0 0" />
      <geometry>
        <mesh
          filename="en.STL"
          scale="0.001 0.001 0.001" />
      </geometry>
    </collision>
    <collision>
      <origin
        xyz="-0.018953737 -0.018953737 0.024"
        rpy="0 0 0" />
      <geometry>
        <mesh
          filename="camera.STL"
          scale="0.001 0.001 0.001" />
      </geometry>
    </collision>
  </link>
  <joint
    name="tool_mount_joint"
    type="fixed">
    <origin
      xyz="0 0 0"
      rpy="0 0 0" />
    <parent
      link="link_6" />
    <child
      link="endoscope_tool" />
  </joint>
  <link
    name="inspection_target">
    <inertial>
      <origin
        xyz="0 0 0"
        rpy="0 0 0" />
      <mass
        value="0.2" />
      <inertia
        ixx="0.0003"
        ixy="0"
        ixz="0"
        iyy="0.0003"
        iyz="0"
        izz="0.0003" />
    </inertial>
    <visual>
      <origin
        xyz="0 0 0"
        rpy="0 0 0" />
      <geometry>
        <box
          size="0.03 0.08 0.08" />
      </geometry>
      <material
        name="target_body">
        <color
          rgba="0.18 0.72 0.44 1" />
      </material>
    </visual>
    <visual>
      <origin
        xyz="0.021 0 0"
        rpy="0 1.5708 0" />
      <geometry>
        <cylinder
          radius="0.012"
          length="0.018" />
      </geometry>
      <material
        name="target_feature_cyl">
        <color
          rgba="0.92 0.96 0.28 1" />
      </material>
    </visual>
    <visual>
      <origin
        xyz="0.018 -0.018 0.02"
        rpy="0 0 0" />
      <geometry>
        <sphere
          radius="0.01" />
      </geometry>
      <material
        name="target_feature_sphere">
        <color
          rgba="0.94 0.3 0.22 1" />
      </material>
    </visual>
    <visual>
      <origin
        xyz="0.018 0.02 -0.018"
        rpy="0 0 0" />
      <geometry>
        <box
          size="0.012 0.02 0.02" />
      </geometry>
      <material
        name="target_feature_box">
        <color
          rgba="0.22 0.72 0.96 1" />
      </material>
    </visual>
    <visual>
      <origin
        xyz="0.05 0 0"
        rpy="0 0 0" />
      <geometry>
        <sphere
          radius="0.018" />
      </geometry>
      <material
        name="target_front_sphere">
        <color
          rgba="0.96 0.2 0.2 1" />
      </material>
    </visual>
    <collision>
      <origin
        xyz="0 0 0"
        rpy="0 0 0" />
      <geometry>
        <box
          size="0.03 0.08 0.08" />
      </geometry>
    </collision>
    <collision>
      <origin
        xyz="0.05 0 0"
        rpy="0 0 0" />
      <geometry>
        <sphere
          radius="0.018" />
      </geometry>
    </collision>
  </link>
  <joint
    name="inspection_target_joint"
    type="fixed">
    <origin
      xyz="-0.61 0 0.497"
      rpy="0 0 0" />
    <parent
      link="base_link" />
    <child
      link="inspection_target" />
  </joint>
</robot>
